<?xml version="1.0"?>
<robot name="robotiq_2f85" xmlns:xacro="http://wiki.ros.org/xacro">

  <!-- Parameters -->
  <xacro:property name="M_PI" value="3.14159265359" />
  
  <!-- Gripper macro -->
  <xacro:macro name="robotiq_2f85_gripper" params="prefix parent *origin">
    
    <!-- Gripper attachment joint -->
    <joint name="${prefix}gripper_attachment" type="fixed">
      <parent link="${parent}"/>
      <child link="${prefix}gripper_base_link"/>
      <xacro:insert_block name="origin"/>
    </joint>
    
    <!-- Gripper base -->
    <link name="${prefix}gripper_base_link">
      <visual>
        <origin xyz="0 0 0" rpy="0 0 0"/>
        <geometry>
          <box size="0.090 0.054 0.050"/>
        </geometry>
        <material name="gripper_material">
          <color rgba="0.2 0.2 0.2 1.0"/>
        </material>
      </visual>
      <collision>
        <origin xyz="0 0 0" rpy="0 0 0"/>
        <geometry>
          <box size="0.090 0.054 0.050"/>
        </geometry>
      </collision>
      <inertial>
        <mass value="0.640"/>
        <origin xyz="0 0 0" rpy="0 0 0"/>
        <inertia ixx="0.001" ixy="0.0" ixz="0.0" iyy="0.001" iyz="0.0" izz="0.001"/>
      </inertial>
    </link>

    <!-- Left finger -->
    <link name="${prefix}left_finger_link">
      <visual>
        <origin xyz="0 0 0.045" rpy="0 0 0"/>
        <geometry>
          <box size="0.015 0.020 0.090"/>
        </geometry>
        <material name="finger_material">
          <color rgba="0.1 0.1 0.1 1.0"/>
        </material>
      </visual>
      <collision>
        <origin xyz="0 0 0.045" rpy="0 0 0"/>
        <geometry>
          <box size="0.015 0.020 0.090"/>
        </geometry>
      </collision>
      <inertial>
        <mass value="0.050"/>
        <origin xyz="0 0 0.045" rpy="0 0 0"/>
        <inertia ixx="0.0001" ixy="0.0" ixz="0.0" iyy="0.0001" iyz="0.0" izz="0.0001"/>
      </inertial>
    </link>

    <!-- Right finger -->
    <link name="${prefix}right_finger_link">
      <visual>
        <origin xyz="0 0 0.045" rpy="0 0 0"/>
        <geometry>
          <box size="0.015 0.020 0.090"/>
        </geometry>
        <material name="finger_material">
          <color rgba="0.1 0.1 0.1 1.0"/>
        </material>
      </visual>
      <collision>
        <origin xyz="0 0 0.045" rpy="0 0 0"/>
        <geometry>
          <box size="0.015 0.020 0.090"/>
        </geometry>
      </collision>
      <inertial>
        <mass value="0.050"/>
        <origin xyz="0 0 0.045" rpy="0 0 0"/>
        <inertia ixx="0.0001" ixy="0.0" ixz="0.0" iyy="0.0001" iyz="0.0" izz="0.0001"/>
      </inertial>
    </link>

    <!-- Left finger joint -->
    <joint name="${prefix}left_finger_joint" type="prismatic">
      <parent link="${prefix}gripper_base_link"/>
      <child link="${prefix}left_finger_link"/>
      <origin xyz="0.0225 -0.015 0.025" rpy="0 0 0"/>
      <axis xyz="1 0 0"/>
      <limit lower="0.0" upper="0.042" effort="235" velocity="0.15"/>
      <dynamics damping="1.0" friction="1.0"/>
    </joint>

    <!-- Right finger joint -->
    <joint name="${prefix}right_finger_joint" type="prismatic">
      <parent link="${prefix}gripper_base_link"/>
      <child link="${prefix}right_finger_link"/>
      <origin xyz="-0.0225 -0.015 0.025" rpy="0 0 0"/>
      <axis xyz="-1 0 0"/>
      <limit lower="0.0" upper="0.042" effort="235" velocity="0.15"/>
      <dynamics damping="1.0" friction="1.0"/>
      <mimic joint="${prefix}left_finger_joint" multiplier="1.0" offset="0.0"/>
    </joint>

    <!-- Gripper tip frame for grasping calculations -->
    <link name="${prefix}gripper_tip_link"/>
    <joint name="${prefix}gripper_tip_joint" type="fixed">
      <parent link="${prefix}gripper_base_link"/>
      <child link="${prefix}gripper_tip_link"/>
      <origin xyz="0 0 0.115" rpy="0 0 0"/>
    </joint>


  </xacro:macro>

</robot>